Workbook

Sheet Hoja1
B1: Matriz de necesidades y satisfactores
B2: Necesidades según categorías axiológicas. | C2: Necesidades según categorías existenciales
C3: SER | D3: TENER | E3: HACER | F3: ESTAR
B4: Subsistencia | C4: (1) Salud física y mental, equilibrio, solidaridad, humor, adaptabilidad | D4: (2) Alimentación, abrigo, trabajo | E4: (3) Alimentar, procrear, descansar, trabajar | F4: (4) Entorno vital, entorno social
C5: 3 | D5: 2 | E5: 2 | F5: 2
B6: Proteccion | C6: (5) Cuidado, adaptabilidad, autonomía, equilibrio, solidaridad | D6: (6) Sistemas de seguros, ahorro, seguridad social, sistemas de salud. legislaciones, derechos, familia. Trabajo | E6: (7) Cooperar, prevenir, planificar, cuidar, curar, defender | F6: (8) Entorno vital, entorno social, morada
C7: 3 | D7: 3 | E7: 3 | F7: 2
B8: Afecto | C8: (9) Autoestima, solidaridad, respeto, tolerancia, generosidad, receptividad, pasión, voluntad, sensualidad, humor | D8: (10) Amistades, parejas, familia, animales domésticos, plantas, jardines | E8: (11) Hacer el amor, acariciar, expresar emociones, compartir, cuidar, cultivar, apreciar | F8: (12) Privacidad, intimidad, hogar, espacios de encuentro
C9: 3 | D9: 2 | E9: 2 | F9: 4
B10: Entendimiento | C10: (13) Conciencia crítica, receptividad, curiosidad, asombro, disciplina, intuición, racionalidad | D10: (14) Literatura, maestros, método, políticas educacionales, políticas comunicacionales | E10: (15) Investigar, estudiar, experimentar, educar, analizar, meditar, interpretar | F10: (16) Ámbitos de interacción formativa: escuelas, universidades, academias, agrupaciones, comunidades, familia
C11: 4 | D11: 3 | E11: 3 | F11: 4
B12: Participación | C12: (17) Adaptabilidad receptividad, solidaridad disposición, convicción entrega, respeto, pasión humor | D12: (18) Derechos, responsabilidades, obligaciones, atribuciones, trabajo | E12: (19) Afiliarse, cooperar, proponer, compartir, discrepar, acatar, dialogar, acordar, opinar | F12: (20) Ámbitos de interacción participativa: partidos, asociaciones, iglesias, comunidades, vecindarios, familias
C13: 4 | D13: 3 | E13: 2 | F13: 3
B14: Ocio | C14: (21) Curiosidad, receptividad, imaginación, despreocupación, humor, tranquilidad, sensualidad | D14: (22) Juegos, espectáculos, fiestas, calma | E14: (23) Divagar, abstraerse, soñar, añorar, fantasear, evocar, relajarse, divertirse, jugar | F14: (24) Privacidad, intimidad, espacios de encuentro, tiempo libre, ambientes, paisajes
C15: 3 | D15: 2 | E15: 3 | F15: 3
B16: Creación | C16: (25) Pasión, voluntad, intuición, imaginación, audacia, racionalidad, autonomía, inventiva, curiosidad | D16: (26) Habilidades, destrezas, método, trabajo | E16: (27) Trabajar, inventar, construir, idear, componer, diseñar, interpretar | F16: (28) Ámbitos de producción y retroalimentación: talleres, ateneos, agrupaciones, audiencias, espacios de expresión, libertad temporal
C17: 3 | D17: 3 | E17: 2 | F17: 3
B18: Identidad | C18: (29) Pertenencia, coherencia, diferenciación, autoestima, asertividad | D18: (30) Símbolos, lenguaje, hábitos, costumbres, grupos de referencia, sexualidad, valores, normas, roles, memoria histórica, trabajo | E18: (31) Comprometerse, integrarse, confrontarse, definirse, conocerse, reconocerse, actualizarse, crecer | F18: (32) Socio-ritmos, entornos de la cotidianeidad, ámbitos de pertenencia, etapas madurativas
C19: 2 | D19: 3 | E19: 1 | F19: 2
B20: Libertad | C20: (33) Autonomía, autoestima, voluntad, pasión, asertividad, apertura, determinación, audacia, rebeldía, tolerancia | D20: (34) Igualdad de derechos | E20: (35) Discrepar, optar, diferenciarse, arriesgar, conocerse, asumirse, desobedecer, meditar | F20: (36) Plasticidad espacio-temporal
C21: 3 | D21: 4 | E21: 2 | F21: 3
B22: Una matriz de necesidades y satisfactores interrelaciona las necesidades, satisfactores y bienes económicos, estos últimos tienen la capacidad de afectar la eficiencia de los satisfactores. Los satisfactores pueden ordenarse y desglosarse dentro de los cruces de una matriz que, por un lado, clasifica las necesidades según las categorías existenciales de ser, tener, hacer y estar; y por el otro, las clasifica según categorías axiológicas de subsistencia, protección, afecto, entendimiento, participación, ocio, creación, identidad y libertad. La matriz que se presenta en el cuadro 1 no es de ninguna manera normativa. Es solo un ejemplo de tipos de satisfactores posibles. De hecho, cada persona o cada grupo puede construir y llenar la suya según sea su cultura, su tiempo, su lugar o sus circunstancias, o bien según sus limitaciones o sus aspiraciones. De la observación de los distintos casilleros de la matriz que contienen propuestas de satisfactores posibles, se desprende que muchos de los satisfactores indicados pueden dar origen a diversos bienes económicos. Si se escoge, por ejemplo, el casillero 15 que indica formas del hacer para satisfacer la necesidad de entendimiento, se encuentran satisfactores como investigar, estudiar, experimentar, educar, analizar, meditar e interpretar. Ellos dan origen a bienes económicos, según sea la cultura y sus recursos, tales como libros, instrumentos de laboratorio, herramientas, computadoras y otros artefactos. La función de estos es, ciertamente, la de potenciar el hacer del entendimiento.
D25: Subsistencia:
B39: ¿Por qué asignaste ese puntaje? Lo Elegí debido A que Me hace Falta En El Momento Mejorar Y Tomarme El Tiempo de las Principales Actividades Cotidianas. ¿Qué debes cambiar o mejorar para aumentar la valoración en las categorías con puntuaciones más bajas? Debo Cambiar Mi Estilo Rutinario Y Empezar A Usarlo de una Manera Más Organizada, Como Es El Sueño, Alimento, Y Mi Vida Social. | E39: ¿Por qué asignaste ese puntaje? Porque Cumplo Con lo Básico de Estas, Pero que Todavía Me Falta Mejorarlas Más Y Prácticar Un Entorno Más de Entretenimiento. ¿Qué debes cambiar o mejorar para aumentar la valoración en las categorías con puntuaciones más bajas? Debo Mejorar Mi Capacidad de Conocer Y Adaptar Nuevos Ambientes, Así Como El Entretenimiento Y la Creatividad, Respectivamente.
B56: ¿Por qué asignaste ese puntaje? Lo Asigné de Esta Manera Porque Requiero de Mejorar Mi Vida Social, Así Como El Hablar Y Compartir Con las Personas y Sus Ambientes. ¿Qué debes cambiar o mejorar para aumentar la valoración en las categorías con puntuaciones más bajas? Debo Cambiar Mi Zona de Confort, Esto Y Con Una Ayuda Psicológica Para Poder Mejorar Mi Entorno Social, Y Evitar Un AutoAislamiento de Todo, O la Soledad. | E56: ¿Por qué asignaste ese puntaje? Debido A que Me Hace Falta Mejorar Una Manera de Trabajar En Nuevas ideas En Mi Vida Cotidiana Y Saberlas Manejar Junto Con lo demás. ¿Qué debes cambiar o mejorar para aumentar la valoración en las categorías con puntuaciones más bajas? Debo Cambiar las Constumbres Y Busca Nuevas ideas Sobre los Métodos de Diseño O inventos que Puedo Utilizar Tanto En los Aprendizajes O Temás Laborales, Como implementarlos Támbien A lo que Es Mi Vida Social Con los demás Y En lo Personal.
B73: ¿Por qué asignaste ese puntaje? Debido A que Me he Visto Escaso A la Hora de Mi Vida Social, Tanto En Expresar Y Sentir Cualquier Afecto A los demás, Así Como Hablar Y Compartir Tanto Con Otras Personas Como En Ciertas Partes de Mi Familia. ¿Qué debes cambiar o mejorar para aumentar la valoración en las categorías con puntuaciones más bajas? Debo Cambiar Mi Educación dada En Mi Entorno Y Proponerme A Buscar Nuevas Amistades Y/o Personas, Animales O Vida Verde Para Mejorar Mi Capacidad de Expresión Y Los Distitntos Afectos que Se Suelen dar por Conocer. | E73: ¿Por qué asignaste ese puntaje? Lo Escogí Porque Me Hace Falta Requerir Más Sobre Mi Conocimiento de Mi Propia Persona Y A Aprender Más Sobre Mis Gustos, Cosas Personales Y lo Negativo O No llamativo Sobre Mi Personalidad. ¿Qué debes cambiar o mejorar para aumentar la valoración en las categorías con puntuaciones más bajas? Debo Mejorar Mi Capacidad Mental Y Psicologica para Entender Mi Capacidad de Conocerme A Mi Mismo y lo que Me Marca Como Propio O de Mi Personalidad, Como Pueden Ser los Deportes, AutoEstima, Madurez, Integridad, Entre Otros.
B90: ¿Por qué asignaste ese puntaje? Porque Me he Visto Muy Bien Educado Según Las Formativas Y Disciplina que he Ejercido, Junto Con lo Básico Sobre investigación Y Literatura. ¿Qué debes cambiar o mejorar para aumentar la valoración en las categorías con puntuaciones más bajas? En Este Caso No Veo Algo Necesario Para Aprender O Capacitar, Más Bien Mejorar Las Capacidades de Estudio y Sobre la Literatura Y Política Como En la Educación. | E90: ¿Por qué asignaste ese puntaje? Lo Elegí Así Porque he Visto Por Cumplido Con lo Básico, Pero que Me hace Falta Más Sobre El Negarse A Ciertas Ocasiones Y Al Arriesgarse Para Cumplir Ciertos Objetivos que Tengo En Mi Mente que Conseguir. ¿Qué debes cambiar o mejorar para aumentar la valoración en las categorías con puntuaciones más bajas? Debo Comprometer Un Compromiso de Aprender A Buscar Una buena Autonomía Y Propias desiciones, Buscando Támbien Una Capacidad de Arriesgarme A Grandes Cosas que Me pueden Ayudar A ir Más Allá de los Propios Limites que Me Propongo A Hacer.
B107: ¿Por qué asignaste ese puntaje? Porque He Visto que he Carecido Con Compartir, Dialogar O Proponer Buenas ideas Hacia los demás, O En Mi Entorno Cotidiano. ¿Qué debes cambiar o mejorar para aumentar la valoración en las categorías con puntuaciones más bajas? Debo Cambiar Y Punto de Vista Y Tomar Ayudas Y Acciones Para Poder Mejorar Esas Capacidades que Hacen Falta Como Metodo de Vida Social.
B110: RESULTADOS
B112: Subsistencia
B113: {=_xlfn.IFS(C5=1,Hoja2!B70,D5=1,Hoja2!B74,E5=1,Hoja2!B78,F5=1,Hoja2!B82)} -> #N/A | D113: =B39 -> ¿Por qué asignaste ese puntaje? Lo Elegí debido A que Me hace Falta En El Momento Mejorar Y Tomarme El Tiempo de las Principales Actividades Cotidianas. ¿Qué debes cambiar o mejorar para aumentar la valoración en las categorías con puntuaciones más bajas? Debo Cambiar Mi Estilo Rutinario Y Empezar A Usarlo de una Manera Más Organizada, Como Es El Sueño, Alimento, Y Mi Vida Social.
B114: {=_xlfn.IFS(C5=1,Hoja2!B71,D5=1,Hoja2!B75,E5=1,Hoja2!B79,F5=1,Hoja2!B83)} -> #N/A
B116: Protección
B117: {=_xlfn.IFS(C7=1,Hoja2!B88,D7=1,Hoja2!B92,E7=1,Hoja2!B96,F7=1,Hoja2!B100)} -> #N/A | D117: =E39 -> ¿Por qué asignaste ese puntaje? Porque Cumplo Con lo Básico de Estas, Pero que Todavía Me Falta Mejorarlas Más Y Prácticar Un Entorno Más de Entretenimiento. ¿Qué debes cambiar o mejorar para aumentar la valoración en las categorías con puntuaciones más bajas? Debo Mejorar Mi Capacidad de Conocer Y Adaptar Nuevos Ambientes, Así Como El Entretenimiento Y la Creatividad, Respectivamente.
B118: {=_xlfn.IFS(C7=1,Hoja2!B89,D7=1,Hoja2!B93,E7=1,Hoja2!B97,F7=1,Hoja2!B101)} -> #N/A
B120: Afecto
B121: {=_xlfn.IFS(C9=1,Hoja2!B106,D9=1,Hoja2!B110,E9=1,Hoja2!B114,F9=1,Hoja2!B118)} -> #N/A | D121: =B56 -> ¿Por qué asignaste ese puntaje? Lo Asigné de Esta Manera Porque Requiero de Mejorar Mi Vida Social, Así Como El Hablar Y Compartir Con las Personas y Sus Ambientes. ¿Qué debes cambiar o mejorar para aumentar la valoración en las categorías con puntuaciones más bajas? Debo Cambiar Mi Zona de Confort, Esto Y Con Una Ayuda Psicológica Para Poder Mejorar Mi Entorno Social, Y Evitar Un AutoAislamiento de Todo, O la Soledad.
B122: {=_xlfn.IFS(C9=1,Hoja2!B107,D9=1,Hoja2!B111,E9=1,Hoja2!B115,F9=1,Hoja2!B119)} -> #N/A
B124: Entendimiento
B125: {=_xlfn.IFS(C11=1,Hoja2!B124,D11=1,Hoja2!B128,E11=1,Hoja2!B132,F11=1,Hoja2!B136)} -> #N/A | D125: =E56 -> ¿Por qué asignaste ese puntaje? Debido A que Me Hace Falta Mejorar Una Manera de Trabajar En Nuevas ideas En Mi Vida Cotidiana Y Saberlas Manejar Junto Con lo demás. ¿Qué debes cambiar o mejorar para aumentar la valoración en las categorías con puntuaciones más bajas? Debo Cambiar las Constumbres Y Busca Nuevas ideas Sobre los Métodos de Diseño O inventos que Puedo Utilizar Tanto En los Aprendizajes O Temás Laborales, Como implementarlos Támbien A lo que Es Mi Vida Social Con los demás Y En lo Personal.
...

Sheet Hoja2
B63: ¡Por supuesto! Aquí está una versión ampliada de las recomendaciones, incluyendo EJEMPLOs prácticos para cada una:
B67: Subsistencia
B69: 1. (1) Salud física y mental:
B70: RECOMENDACIÓN: Evalúa tus hábitos diarios y establece pequeñas metas para mejorar tu bienestar. Incorpora actividades como caminar 30 minutos al día, meditar antes de dormir o practicar un deporte que disfrutes. Además, si sientes estrés o ansiedad, busca apoyo emocional o terapéutico.
B71: EJEMPLO: Si no tienes una rutina de ejercicio, comienza con una caminata breve después de las comidas y aumenta gradualmente el tiempo.
B73: 2. (2) Alimentación, abrigo, trabajo:
B74: RECOMENDACIÓN: Asegúrate de cubrir tus necesidades básicas a través de la planificación. Por EJEMPLO, organiza un presupuesto semanal para alimentos y ropa, priorizando calidad sobre cantidad. Si necesitas empleo, revisa tu currículum y explora oportunidades locales.
B75: EJEMPLO: Si tu dieta no es equilibrada, incluye una fruta y una verdura en cada comida para mejorar tu nutrición.
B77: 3. (3) Alimentar, procrear, descansar, trabajar:
B78: RECOMENDACIÓN: Establece un horario equilibrado entre el trabajo, el descanso y la vida personal. Asegúrate de dormir al menos 7 horas y desconéctate de las pantallas antes de acostarte.
B79: EJEMPLO: Si trabajas largas horas sin descanso, programa pausas cada dos horas para caminar o tomar agua.
B81: 4. (4) Entorno vital, entorno social:
... B233: ¡Espero que estas recomendaciones ampliadas sean útiles! Si necesitas ajustar algo más o agregar más EJEMPLOs específicos, no dudes en pedírmelo. 😊
